<?xml version="1.0" encoding="UTF-8"?>
<!-- Generated by org.testng.reporters.JUnitReportReporter -->
<testsuite skipped="4" hostname="LAPTOP-JIBR9C35" name="practice.TestNgAnnotation" tests="5" failures="1" timestamp="25 Nov 2021 17:56:49 GMT" time="0.046" errors="0">
  <testcase name="test4" time="0.046" classname="practice.TestNgAnnotation">
    <failure type="java.lang.AssertionError" message="The following asserts failed:
	good expected [good] but found [Result not matched],
	Mayur expected [ashish] but found [Result not matched],
	best expected [best] but found [Result not matched]">
      <![CDATA[java.lang.AssertionError: The following asserts failed:
good expected [good] but found [Result not matched],
Mayur expected [ashish] but found [Result not matched],
best expected [best] but found [Result not matched]
at org.testng.asserts.SoftAssert.assertAll(SoftAssert.java:43)
at practice.TestNgAnnotation.test4(TestNgAnnotation.java:88)
at sun.reflect.NativeMethodAccessorImpl.invoke0(Native Method)
at sun.reflect.NativeMethodAccessorImpl.invoke(Unknown Source)
at sun.reflect.DelegatingMethodAccessorImpl.invoke(Unknown Source)
at java.lang.reflect.Method.invoke(Unknown Source)
at org.testng.internal.MethodInvocationHelper.invokeMethod(MethodInvocationHelper.java:124)
at org.testng.internal.Invoker.invokeMethod(Invoker.java:583)
at org.testng.internal.Invoker.invokeTestMethod(Invoker.java:719)
at org.testng.internal.Invoker.invokeTestMethods(Invoker.java:989)
at org.testng.internal.TestMethodWorker.invokeTestMethods(TestMethodWorker.java:125)
at org.testng.internal.TestMethodWorker.run(TestMethodWorker.java:109)
at org.testng.TestRunner.privateRun(TestRunner.java:648)
at org.testng.TestRunner.run(TestRunner.java:505)
at org.testng.SuiteRunner.runTest(SuiteRunner.java:455)
at org.testng.SuiteRunner.runSequentially(SuiteRunner.java:450)
at org.testng.SuiteRunner.privateRun(SuiteRunner.java:415)
at org.testng.SuiteRunner.run(SuiteRunner.java:364)
at org.testng.SuiteRunnerWorker.runSuite(SuiteRunnerWorker.java:52)
at org.testng.SuiteRunnerWorker.run(SuiteRunnerWorker.java:84)
at org.testng.TestNG.runSuitesSequentially(TestNG.java:1208)
at org.testng.TestNG.runSuitesLocally(TestNG.java:1137)
at org.testng.TestNG.runSuites(TestNG.java:1049)
at org.testng.TestNG.run(TestNG.java:1017)
at org.testng.remote.AbstractRemoteTestNG.run(AbstractRemoteTestNG.java:132)
at org.testng.remote.RemoteTestNG.initAndRun(RemoteTestNG.java:236)
at org.testng.remote.RemoteTestNG.main(RemoteTestNG.java:81)
]]>
    </failure>
  </testcase> <!-- test4 -->
  <testcase name="test" classname="practice.TestNgAnnotation">
    <skipped/>
  </testcase> <!-- test -->
  <testcase name="test5" classname="practice.TestNgAnnotation">
    <skipped/>
  </testcase> <!-- test5 -->
  <testcase name="test2" classname="practice.TestNgAnnotation">
    <skipped/>
  </testcase> <!-- test2 -->
  <testcase name="test3" classname="practice.TestNgAnnotation">
    <skipped/>
  </testcase> <!-- test3 -->
</testsuite> <!-- practice.TestNgAnnotation -->
